Workbook

Sheet 1_Parameters
A1: Comprehensive Cost Model with LCOH
A3: === BASELINE PRODUCTION ===
A4: Ethylene Baseline Capacity | B4: 11962 | C4: kt/year | D4: 11 NCC facilities
A5: Shaheen Multiplier (2050) | B5: 1.15
A7: === NCC-H2 TECHNOLOGY ===
A8: H2 Intensity | B8: 0.56 | C8: ton H2/ton C2H4 | D8: Lummus Tech 2023
A9: CAPEX 2025 | B9: 1550 | C9: $/t-C2H4/yr
A10: CAPEX 2030 | B10: 1300 | C10: $/t-C2H4/yr
A11: CAPEX 2040 | B11: 935 | C11: $/t-C2H4/yr
A12: CAPEX 2050 | B12: 780 | C12: $/t-C2H4/yr
A13: OPEX (% of CAPEX) | B13: 4 | C13: %
A14: Lifetime | B14: 25 | C14: years
A16: === NCC-ELECTRICITY TECHNOLOGY ===
A17: Elec Intensity | B17: 5 | C17: MWh/ton C2H4 | D17: BASF/SABIC/Linde 2024
A18: CAPEX 2025 | B18: 1500 | C18: $/t-C2H4/yr
A19: CAPEX 2030 | B19: 1350 | C19: $/t-C2H4/yr
A20: CAPEX 2040 | B20: 1050 | C20: $/t-C2H4/yr
A21: CAPEX 2050 | B21: 900 | C21: $/t-C2H4/yr
A22: OPEX (% of CAPEX) | B22: 4 | C22: %
A23: Lifetime | B23: 25 | C23: years
A25: === ELECTROLYZER (for LCOH) ===
A26: Efficiency (HHV) | B26: 70 | C26: % | D26: PEM/Alkaline typical
A27: CAPEX 2025 | B27: 1200 | C27: $/kW
A28: CAPEX 2030 | B28: 800 | C28: $/kW
A29: CAPEX 2040 | B29: 500 | C29: $/kW
A30: CAPEX 2050 | B30: 300 | C30: $/kW
A31: OPEX (% of CAPEX) | B31: 2 | C31: %
A32: Lifetime | B32: 20 | C32: years
A33: Capacity Factor | B33: 90 | C33: %
A34: Stack Replacement | B34: 10 | C34: years | D34: Interval
A35: Stack Cost (% of CAPEX) | B35: 40 | C35: %
A36: H2 HHV | B36: 39.4 | C36: kWh/kg | D36: Higher Heating Value
A38: === STREAMLIT BASELINE VALUES (2050) ===
A39: Shaheen H2 Demand | B39: 7703.5 | C39: kt/year
A40: Shaheen Elec Demand | B40: 164.5 | C40: TWh/year

Sheet 2_Prices
A1: Year | B1: H2 Price ($/kg) | C1: RE Price ($/MWh) | D1: Grid Price ($/MWh) | E1: H2-Elec Spread
A2: 2025 | B2: 6.73 | C2: 129.29 | D2: 100 | E2: =B2-(C2*56.3/1000)
A3: 2026 | B3: 6.56 | C3: 134.46 | D3: 103.66 | E3: =B3-(C3*56.3/1000)
A4: 2027 | B4: 6.39 | C4: 139.84 | D4: 107.31 | E4: =B4-(C4*56.3/1000)
A5: 2028 | B5: 6.22 | C5: 145.43 | D5: 110.97 | E5: =B5-(C5*56.3/1000)
A6: 2029 | B6: 6.05 | C6: 151.25 | D6: 114.62 | E6: =B6-(C6*56.3/1000)
A7: 2030 | B7: 5.88 | C7: 157.3 | D7: 118.28 | E7: =B7-(C7*56.3/1000)
A8: 2031 | B8: 5.71 | C8: 163.59 | D8: 121.93 | E8: =B8-(C8*56.3/1000)
A9: 2032 | B9: 5.53 | C9: 170.13 | D9: 125.59 | E9: =B9-(C9*56.3/1000)
A10: 2033 | B10: 5.36 | C10: 176.94 | D10: 129.24 | E10: =B10-(C10*56.3/1000)
A11: 2034 | B11: 5.19 | C11: 184.02 | D11: 132.9 | E11: =B11-(C11*56.3/1000)
A12: 2035 | B12: 5.02 | C12: 191.38 | D12: 136.55 | E12: =B12-(C12*56.3/1000)
A13: 2036 | B13: 4.84 | C13: 191.38 | D13: 140.21 | E13: =B13-(C13*56.3/1000)
... A27: 2050 | B27: 2.63 | C27: 191.38 | D27: 191.38 | E27: =B27-(C27*56.3/1000)

Sheet 3_LCOH
A1: Levelized Cost of Hydrogen (LCOH) Calculation
A3: === LCOH FORMULA ===
A4: LCOH = (CAPEX_ann + OPEX + Elec_Cost) / H2_produced
A6: Where:
A7: CAPEX_ann = CAPEX / Lifetime
A8: OPEX = CAPEX × OPEX%
A9: Elec_Cost = Elec_price × Elec_consumption
A10: Elec_consumption = H2_HHV / Efficiency
A12: === LCOH BY YEAR ===
A13: Year | B13: Electrolyzer CAPEX ($/kW) | C13: Elec Price ($/MWh) | D13: Elec (kWh/kg H2) | E13: LCOH ($/kg)
A14: 2025 | B14: 1200 | C14: ='2_Prices'!C2 | D14: 56.3 | E14: =B14*0.000356*(1+'1_Parameters'!B31/100) + C14*D14/1000
A15: 2026 | B15: 1120 | C15: ='2_Prices'!C3 | D15: 56.3 | E15: =B15*0.000356*(1+'1_Parameters'!B31/100) + C15*D15/1000
A16: 2027 | B16: 1040 | C16: ='2_Prices'!C4 | D16: 56.3 | E16: =B16*0.000356*(1+'1_Parameters'!B31/100) + C16*D16/1000
A17: 2028 | B17: 960 | C17: ='2_Prices'!C5 | D17: 56.3 | E17: =B17*0.000356*(1+'1_Parameters'!B31/100) + C17*D17/1000
A18: 2029 | B18: 880 | C18: ='2_Prices'!C6 | D18: 56.3 | E18: =B18*0.000356*(1+'1_Parameters'!B31/100) + C18*D18/1000
A19: 2030 | B19: 800 | C19: ='2_Prices'!C7 | D19: 56.3 | E19: =B19*0.000356*(1+'1_Parameters'!B31/100) + C19*D19/1000
A20: 2031 | B20: 770 | C20: ='2_Prices'!C8 | D20: 56.3 | E20: =B20*0.000356*(1+'1_Parameters'!B31/100) + C20*D20/1000
A21: 2032 | B21: 740 | C21: ='2_Prices'!C9 | D21: 56.3 | E21: =B21*0.000356*(1+'1_Parameters'!B31/100) + C21*D21/1000
A22: 2033 | B22: 710 | C22: ='2_Prices'!C10 | D22: 56.3 | E22: =B22*0.000356*(1+'1_Parameters'!B31/100) + C22*D22/1000
A23: 2034 | B23: 680 | C23: ='2_Prices'!C11 | D23: 56.3 | E23: =B23*0.000356*(1+'1_Parameters'!B31/100) + C23*D23/1000
A24: 2035 | B24: 650 | C24: ='2_Prices'!C12 | D24: 56.3 | E24: =B24*0.000356*(1+'1_Parameters'!B31/100) + C24*D24/1000
A25: 2036 | B25: 620 | C25: ='2_Prices'!C13 | D25: 56.3 | E25: =B25*0.000356*(1+'1_Parameters'!B31/100) + C25*D25/1000
A26: 2037 | B26: 590 | C26: ='2_Prices'!C14 | D26: 56.3 | E26: =B26*0.000356*(1+'1_Parameters'!B31/100) + C26*D26/1000
A27: 2038 | B27: 560 | C27: ='2_Prices'!C15 | D27: 56.3 | E27: =B27*0.000356*(1+'1_Parameters'!B31/100) + C27*D27/1000
A28: 2039 | B28: 530 | C28: ='2_Prices'!C16 | D28: 56.3 | E28: =B28*0.000356*(1+'1_Parameters'!B31/100) + C28*D28/1000
A29: 2040 | B29: 500 | C29: ='2_Prices'!C17 | D29: 56.3 | E29: =B29*0.000356*(1+'1_Parameters'!B31/100) + C29*D29/1000
A30: 2041 | B30: 480 | C30: ='2_Prices'!C18 | D30: 56.3 | E30: =B30*0.000356*(1+'1_Parameters'!B31/100) + C30*D30/1000
A31: 2042 | B31: 460 | C31: ='2_Prices'!C19 | D31: 56.3 | E31: =B31*0.000356*(1+'1_Parameters'!B31/100) + C31*D31/1000
A32: 2043 | B32: 440 | C32: ='2_Prices'!C20 | D32: 56.3 | E32: =B32*0.000356*(1+'1_Parameters'!B31/100) + C32*D32/1000
A33: 2044 | B33: 420 | C33: ='2_Prices'!C21 | D33: 56.3 | E33: =B33*0.000356*(1+'1_Parameters'!B31/100) + C33*D33/1000
A34: 2045 | B34: 400 | C34: ='2_Prices'!C22 | D34: 56.3 | E34: =B34*0.000356*(1+'1_Parameters'!B31/100) + C34*D34/1000
A35: 2046 | B35: 380 | C35: ='2_Prices'!C23 | D35: 56.3 | E35: =B35*0.000356*(1+'1_Parameters'!B31/100) + C35*D35/1000
A36: 2047 | B36: 360 | C36: ='2_Prices'!C24 | D36: 56.3 | E36: =B36*0.000356*(1+'1_Parameters'!B31/100) + C36*D36/1000
A37: 2048 | B37: 340 | C37: ='2_Prices'!C25 | D37: 56.3 | E37: =B37*0.000356*(1+'1_Parameters'!B31/100) + C37*D37/1000
A38: 2049 | B38: 320 | C38: ='2_Prices'!C26 | D38: 56.3 | E38: =B38*0.000356*(1+'1_Parameters'!B31/100) + C38*D38/1000
A39: 2050 | B39: 300 | C39: ='2_Prices'!C27 | D39: 56.3 | E39: =B39*0.000356*(1+'1_Parameters'!B31/100) + C39*D39/1000
A41: === COMPARISON ===
A42: Year | B42: LCOH ($/kg) | C42: Market H2 ($/kg) | D42: Difference | E42: Cheaper Option
A43: 2025 | B43: =E14 | C43: ='2_Prices'!B2 | D43: =C43-B43 | E43: =IF(B43<C43,"LCOH (Make)","Market H2 (Buy)")
A44: 2030 | B44: =E19 | C44: ='2_Prices'!B7 | D44: =C44-B44 | E44: =IF(B44<C44,"LCOH (Make)","Market H2 (Buy)")
...

Sheet 4_NCC_Costs
A1: Year | B1: NCC-H2 CAPEX ($B) | C1: NCC-H2 OPEX ($B) | D1: NCC-H2 Fuel ($B) | E1: NCC-H2 Total ($B) | F1: NCC-Elec CAPEX ($B) | G1: NCC-Elec OPEX ($B) | H1: NCC-Elec Fuel ($B) | I1: NCC-Elec Total ($B) | J1: Winner
A2: 2025 | B2: 0.742 | C2: 0.03 | D2: 0.045 | E2: 0.816 | F2: 0.718 | G2: 0.029 | H2: 0.008 | I2: 0.754 | J2: NCC-Elec
A3: 2026 | B3: 0.825 | C3: 0.033 | D3: 0.051 | E3: 0.909 | F3: 0.809 | G3: 0.032 | H3: 0.009 | I3: 0.85 | J3: NCC-Elec
A4: 2027 | B4: 0.798 | C4: 0.032 | D4: 0.049 | E4: 0.879 | F4: 0.792 | G4: 0.032 | H4: 0.01 | I4: 0.834 | J4: NCC-Elec
A5: 2028 | B5: 0.77 | C5: 0.031 | D5: 0.048 | E5: 0.849 | F5: 0.776 | G5: 0.031 | H5: 0.01 | I5: 0.817 | J5: NCC-Elec
A6: 2029 | B6: 0.743 | C6: 0.03 | D6: 0.047 | E6: 0.819 | F6: 0.759 | G6: 0.03 | H6: 0.01 | I6: 0.8 | J6: NCC-Elec
A7: 2030 | B7: 0.715 | C7: 0.029 | D7: 0.045 | E7: 0.789 | F7: 0.743 | G7: 0.03 | H7: 0.011 | I7: 0.783 | J7: NCC-Elec
A8: 2031 | B8: 0.695 | C8: 0.028 | D8: 0.044 | E8: 0.767 | F8: 0.726 | G8: 0.029 | H8: 0.011 | I8: 0.767 | J8: NCC-Elec
A9: 2032 | B9: 0.675 | C9: 0.027 | D9: 0.043 | E9: 0.745 | F9: 0.71 | G9: 0.028 | H9: 0.012 | I9: 0.75 | J9: NCC-H2
A10: 2033 | B10: 0.655 | C10: 0.026 | D10: 0.041 | E10: 0.723 | F10: 0.693 | G10: 0.028 | H10: 0.012 | I10: 0.733 | J10: NCC-H2
A11: 2034 | B11: 0.635 | C11: 0.025 | D11: 0.04 | E11: 0.7 | F11: 0.677 | G11: 0.027 | H11: 0.013 | I11: 0.717 | J11: NCC-H2
A12: 2035 | B12: 0.615 | C12: 0.025 | D12: 0.039 | E12: 0.678 | F12: 0.66 | G12: 0.026 | H12: 0.013 | I12: 0.7 | J12: NCC-H2
A13: 2036 | B13: 0.595 | C13: 0.024 | D13: 0.037 | E13: 0.656 | F13: 0.644 | G13: 0.026 | H13: 0.013 | I13: 0.683 | J13: NCC-H2
... A27: 2050 | B27: 0.429 | C27: 0.017 | D27: 0.02 | E27: 0.467 | F27: 0.495 | G27: 0.02 | H27: 0.013 | I27: 0.528 | J27: NCC-H2
A28: CUMULATIVE (2030-2050) | B28: =SUM(B7:B27) | C28: =SUM(C7:C27) | D28: =SUM(D7:D27) | E28: =SUM(E7:E27) | F28: =SUM(F7:F27) | G28: =SUM(G7:G27) | H28: =SUM(H7:H27) | I28: =SUM(I7:I27)

Sheet 5_MACC
A1: Marginal Abatement Cost Curve (MACC) Summary
A3: === MACC FORMULA ===
A4: MACC = CAPEX_ann + OPEX_ann + Fuel_Cost_Diff
A5: (All costs per tCO2 abated)
A7: === MACC BY YEAR ($/tCO2) ===
A8: Year | B8: NCC-H2 MACC | C8: NCC-Elec MACC | D8: Cheaper | E8: Cost Difference
A9: 2025 | B9: 2017.7 | C9: 373.1 | D9: NCC-Elec | E9: 1644.7
A10: 2026 | B10: 1966.4 | C10: 386 | D10: NCC-Elec | E10: 1580.4
A11: 2027 | B11: 1915.1 | C11: 399.5 | D11: NCC-Elec | E11: 1515.5
A12: 2028 | B12: 1863.7 | C12: 413.6 | D12: NCC-Elec | E12: 1450.1
A13: 2029 | B13: 1812.4 | C13: 428.2 | D13: NCC-Elec | E13: 1384.1
A14: 2030 | B14: 1761 | C14: 443.5 | D14: NCC-Elec | E14: 1317.5
A15: 2031 | B15: 1709.4 | C15: 459.4 | D15: NCC-Elec | E15: 1250
A16: 2032 | B16: 1657.7 | C16: 476 | D16: NCC-Elec | E16: 1181.7
A17: 2033 | B17: 1606 | C17: 493.2 | D17: NCC-Elec | E17: 1112.8
A18: 2034 | B18: 1554.4 | C18: 511.2 | D18: NCC-Elec | E18: 1043.2
A19: 2035 | B19: 1502.7 | C19: 529.9 | D19: NCC-Elec | E19: 972.8
A20: 2036 | B20: 1451.6 | C20: 529.2 | D20: NCC-Elec | E20: 922.4
... A34: 2050 | B34: 791.1 | C34: 523.3 | D34: NCC-Elec | E34: 267.8

Sheet 6_Summary
A1: Cost & LCOH Summary Dashboard
A3: === KEY FINDINGS (2050) ===
A4: Metric | B4: NCC-H2 | C4: NCC-Electricity | D4: Winner
A5: MACC ($/tCO2) | B5: ='5_MACC'!B34 | C5: ='5_MACC'!C34 | D5: ='5_MACC'!D34
A6: Annual Cost ($B) | B6: ='4_NCC_Costs'!E27 | C6: ='4_NCC_Costs'!I27
A7: Cumulative Cost 2030-2050 ($B) | B7: ='4_NCC_Costs'!E28 | C7: ='4_NCC_Costs'!I28
A9: === LCOH vs MARKET H2 (2050) ===
A10: LCOH ($/kg) | B10: ='3_LCOH'!E39
A11: Market H2 ($/kg) | B11: ='2_Prices'!B27
A12: Recommendation | B12: ='3_LCOH'!E48
A14: === ENERGY DEMAND (Shaheen 2050) ===
A15: H2 Demand (NCC-H2 pathway) | B15: ='1_Parameters'!B39 | C15: kt/year
A16: Electricity Demand (NCC-Elec pathway) | B16: ='1_Parameters'!B40 | C16: TWh/year
A18: === INSIGHTS ===
A19: 1. H2 vs Elec Decision | B19: Depends on H2 price trajectory vs RE price
A20: 2. LCOH Trend | B20: Decreasing as electrolyzer CAPEX falls
A21: 3. Make vs Buy | B21: By 2040, producing H2 (LCOH) cheaper than buying
A22: 4. Cost Dominance | B22: Fuel cost > CAPEX for both pathways

Sheet 7_Breakeven
A1: LCOH Breakeven Analysis
A3: === KEY QUESTION ===
A4: At what electricity price does LCOH equal market H2 price?
A6: === BREAKEVEN CALCULATION ===
A7: Year | B7: Market H2 ($/kg) | C7: Electrolyzer CAPEX ($/kW) | D7: Breakeven Elec ($/MWh) | E7: Current RE Price ($/MWh)
A8: 2025 | B8: 6.73 | C8: 1200 | D8: 108.9 | E8: 129.3
A9: 2030 | B9: 5.88 | C9: 800 | D9: 97.3 | E9: 157.3
A10: 2040 | B10: 4.16 | C10: 500 | D10: 69.5 | E10: 191.4
A11: 2050 | B11: 2.63 | C11: 300 | D11: 44 | E11: 191.4
A13: === INTERPRETATION ===
A14: • Breakeven decreases over time (market H2 getting cheaper)
A15: • Current RE prices are HIGHER than breakeven
A16: • To make green H2 cost-competitive:
A17: - Need RE prices < $100/MWh by 2030
A18: - Need RE prices < $70/MWh by 2040
A19: - Need RE prices < $45/MWh by 2050
A21: === SENSITIVITY: LCOH AT DIFFERENT ELEC PRICES ===
A22: Elec Price ($/MWh) | B22: LCOH 2025 | C22: LCOH 2030 | D22: LCOH 2040 | E22: LCOH 2050
A23: 50 | B23: 3.41 | C23: 3.21 | D23: 3.06 | E23: 2.96
A24: 75 | B24: 4.82 | C24: 4.62 | D24: 4.47 | E24: 4.37
A25: 100 | B25: 6.23 | C25: 6.03 | D25: 5.88 | E25: 5.78
A26: 125 | B26: 7.64 | C26: 7.44 | D26: 7.29 | E26: 7.19
A27: 150 | B27: 9.04 | C27: 8.84 | D27: 8.69 | E27: 8.59
A28: 175 | B28: 10.45 | C28: 10.25 | D28: 10.1 | E28: 10
A29: 200 | B29: 11.86 | C29: 11.66 | D29: 11.51 | E29: 11.41
A30: Market H2 Price | B30: 6.73 | C30: 5.88 | D30: 4.16 | E30: 2.63
